2024-08-21 14:35:43,515 (19190/MainThread) litecli.main ERROR - sql: 'select * from u', error: OperationalError('no such table: u')
2024-08-21 14:35:43,518 (19190/MainThread) litecli.main ERROR - traceback: 'Traceback (most recent call last):\n  File "/home/linuxbrew/.linuxbrew/Cellar/litecli/1.11.0/libexec/lib/python3.12/site-packages/litecli/sqlexecute.py", line 125, in run\n    for result in special.execute(cur, sql):\n                  ^^^^^^^^^^^^^^^^^^^^^^^^^\n  File "/home/linuxbrew/.linuxbrew/Cellar/litecli/1.11.0/libexec/lib/python3.12/site-packages/litecli/packages/special/main.py", line 109, in execute\n    raise CommandNotFound\nlitecli.packages.special.main.CommandNotFound\n\nDuring handling of the above exception, another exception occurred:\n\nTraceback (most recent call last):\n  File "/home/linuxbrew/.linuxbrew/Cellar/litecli/1.11.0/libexec/lib/python3.12/site-packages/litecli/main.py", line 453, in one_iteration\n    for title, cur, headers, status in res:\n                                       ^^^\n  File "/home/linuxbrew/.linuxbrew/Cellar/litecli/1.11.0/libexec/lib/python3.12/site-packages/litecli/sqlexecute.py", line 132, in run\n    cur.execute(sql)\nsqlite3.OperationalError: no such table: u\n'
2024-08-21 14:35:48,424 (19190/MainThread) litecli.main ERROR - sql: 'select * from us', error: OperationalError('no such table: us')
2024-08-21 14:35:48,424 (19190/MainThread) litecli.main ERROR - traceback: 'Traceback (most recent call last):\n  File "/home/linuxbrew/.linuxbrew/Cellar/litecli/1.11.0/libexec/lib/python3.12/site-packages/litecli/sqlexecute.py", line 125, in run\n    for result in special.execute(cur, sql):\n                  ^^^^^^^^^^^^^^^^^^^^^^^^^\n  File "/home/linuxbrew/.linuxbrew/Cellar/litecli/1.11.0/libexec/lib/python3.12/site-packages/litecli/packages/special/main.py", line 109, in execute\n    raise CommandNotFound\nlitecli.packages.special.main.CommandNotFound\n\nDuring handling of the above exception, another exception occurred:\n\nTraceback (most recent call last):\n  File "/home/linuxbrew/.linuxbrew/Cellar/litecli/1.11.0/libexec/lib/python3.12/site-packages/litecli/main.py", line 453, in one_iteration\n    for title, cur, headers, status in res:\n                                       ^^^\n  File "/home/linuxbrew/.linuxbrew/Cellar/litecli/1.11.0/libexec/lib/python3.12/site-packages/litecli/sqlexecute.py", line 132, in run\n    cur.execute(sql)\nsqlite3.OperationalError: no such table: us\n'
2024-08-21 14:45:49,924 (19383/MainThread) litecli.main ERROR - sql: 'select * from blogs.id == 1;', error: OperationalError('near "==": syntax error')
2024-08-21 14:45:49,926 (19383/MainThread) litecli.main ERROR - traceback: 'Traceback (most recent call last):\n  File "/home/linuxbrew/.linuxbrew/Cellar/litecli/1.11.0/libexec/lib/python3.12/site-packages/litecli/sqlexecute.py", line 125, in run\n    for result in special.execute(cur, sql):\n                  ^^^^^^^^^^^^^^^^^^^^^^^^^\n  File "/home/linuxbrew/.linuxbrew/Cellar/litecli/1.11.0/libexec/lib/python3.12/site-packages/litecli/packages/special/main.py", line 109, in execute\n    raise CommandNotFound\nlitecli.packages.special.main.CommandNotFound\n\nDuring handling of the above exception, another exception occurred:\n\nTraceback (most recent call last):\n  File "/home/linuxbrew/.linuxbrew/Cellar/litecli/1.11.0/libexec/lib/python3.12/site-packages/litecli/main.py", line 453, in one_iteration\n    for title, cur, headers, status in res:\n                                       ^^^\n  File "/home/linuxbrew/.linuxbrew/Cellar/litecli/1.11.0/libexec/lib/python3.12/site-packages/litecli/sqlexecute.py", line 132, in run\n    cur.execute(sql)\nsqlite3.OperationalError: near "==": syntax error\n'
2024-08-21 14:45:55,274 (19383/MainThread) litecli.main ERROR - sql: 'select * from blogs.id = 1;', error: OperationalError('near "=": syntax error')
2024-08-21 14:45:55,275 (19383/MainThread) litecli.main ERROR - traceback: 'Traceback (most recent call last):\n  File "/home/linuxbrew/.linuxbrew/Cellar/litecli/1.11.0/libexec/lib/python3.12/site-packages/litecli/sqlexecute.py", line 125, in run\n    for result in special.execute(cur, sql):\n                  ^^^^^^^^^^^^^^^^^^^^^^^^^\n  File "/home/linuxbrew/.linuxbrew/Cellar/litecli/1.11.0/libexec/lib/python3.12/site-packages/litecli/packages/special/main.py", line 109, in execute\n    raise CommandNotFound\nlitecli.packages.special.main.CommandNotFound\n\nDuring handling of the above exception, another exception occurred:\n\nTraceback (most recent call last):\n  File "/home/linuxbrew/.linuxbrew/Cellar/litecli/1.11.0/libexec/lib/python3.12/site-packages/litecli/main.py", line 453, in one_iteration\n    for title, cur, headers, status in res:\n                                       ^^^\n  File "/home/linuxbrew/.linuxbrew/Cellar/litecli/1.11.0/libexec/lib/python3.12/site-packages/litecli/sqlexecute.py", line 132, in run\n    cur.execute(sql)\nsqlite3.OperationalError: near "=": syntax error\n'
2024-08-21 16:54:12,692 (19383/MainThread) litecli.main ERROR - sql: 'drop * from users;', error: OperationalError('near "*": syntax error')
2024-08-21 16:54:12,703 (19383/MainThread) litecli.main ERROR - traceback: 'Traceback (most recent call last):\n  File "/home/linuxbrew/.linuxbrew/Cellar/litecli/1.11.0/libexec/lib/python3.12/site-packages/litecli/sqlexecute.py", line 125, in run\n    for result in special.execute(cur, sql):\n                  ^^^^^^^^^^^^^^^^^^^^^^^^^\n  File "/home/linuxbrew/.linuxbrew/Cellar/litecli/1.11.0/libexec/lib/python3.12/site-packages/litecli/packages/special/main.py", line 109, in execute\n    raise CommandNotFound\nlitecli.packages.special.main.CommandNotFound\n\nDuring handling of the above exception, another exception occurred:\n\nTraceback (most recent call last):\n  File "/home/linuxbrew/.linuxbrew/Cellar/litecli/1.11.0/libexec/lib/python3.12/site-packages/litecli/main.py", line 453, in one_iteration\n    for title, cur, headers, status in res:\n                                       ^^^\n  File "/home/linuxbrew/.linuxbrew/Cellar/litecli/1.11.0/libexec/lib/python3.12/site-packages/litecli/sqlexecute.py", line 132, in run\n    cur.execute(sql)\nsqlite3.OperationalError: near "*": syntax error\n'
2024-08-21 16:54:30,768 (19383/MainThread) litecli.main ERROR - sql: 'drop users;', error: OperationalError('near "users": syntax error')
2024-08-21 16:54:30,769 (19383/MainThread) litecli.main ERROR - traceback: 'Traceback (most recent call last):\n  File "/home/linuxbrew/.linuxbrew/Cellar/litecli/1.11.0/libexec/lib/python3.12/site-packages/litecli/sqlexecute.py", line 125, in run\n    for result in special.execute(cur, sql):\n                  ^^^^^^^^^^^^^^^^^^^^^^^^^\n  File "/home/linuxbrew/.linuxbrew/Cellar/litecli/1.11.0/libexec/lib/python3.12/site-packages/litecli/packages/special/main.py", line 109, in execute\n    raise CommandNotFound\nlitecli.packages.special.main.CommandNotFound\n\nDuring handling of the above exception, another exception occurred:\n\nTraceback (most recent call last):\n  File "/home/linuxbrew/.linuxbrew/Cellar/litecli/1.11.0/libexec/lib/python3.12/site-packages/litecli/main.py", line 453, in one_iteration\n    for title, cur, headers, status in res:\n                                       ^^^\n  File "/home/linuxbrew/.linuxbrew/Cellar/litecli/1.11.0/libexec/lib/python3.12/site-packages/litecli/sqlexecute.py", line 132, in run\n    cur.execute(sql)\nsqlite3.OperationalError: near "users": syntax error\n'
2024-08-21 16:55:43,790 (19383/MainThread) litecli.main ERROR - sql: 'delete * from users;', error: OperationalError('near "*": syntax error')
2024-08-21 16:55:43,791 (19383/MainThread) litecli.main ERROR - traceback: 'Traceback (most recent call last):\n  File "/home/linuxbrew/.linuxbrew/Cellar/litecli/1.11.0/libexec/lib/python3.12/site-packages/litecli/sqlexecute.py", line 125, in run\n    for result in special.execute(cur, sql):\n                  ^^^^^^^^^^^^^^^^^^^^^^^^^\n  File "/home/linuxbrew/.linuxbrew/Cellar/litecli/1.11.0/libexec/lib/python3.12/site-packages/litecli/packages/special/main.py", line 109, in execute\n    raise CommandNotFound\nlitecli.packages.special.main.CommandNotFound\n\nDuring handling of the above exception, another exception occurred:\n\nTraceback (most recent call last):\n  File "/home/linuxbrew/.linuxbrew/Cellar/litecli/1.11.0/libexec/lib/python3.12/site-packages/litecli/main.py", line 453, in one_iteration\n    for title, cur, headers, status in res:\n                                       ^^^\n  File "/home/linuxbrew/.linuxbrew/Cellar/litecli/1.11.0/libexec/lib/python3.12/site-packages/litecli/sqlexecute.py", line 132, in run\n    cur.execute(sql)\nsqlite3.OperationalError: near "*": syntax error\n'
2024-08-21 16:56:19,580 (19383/MainThread) litecli.main ERROR - sql: 'delete column from users;', error: OperationalError('near "column": syntax error')
2024-08-21 16:56:19,581 (19383/MainThread) litecli.main ERROR - traceback: 'Traceback (most recent call last):\n  File "/home/linuxbrew/.linuxbrew/Cellar/litecli/1.11.0/libexec/lib/python3.12/site-packages/litecli/sqlexecute.py", line 125, in run\n    for result in special.execute(cur, sql):\n                  ^^^^^^^^^^^^^^^^^^^^^^^^^\n  File "/home/linuxbrew/.linuxbrew/Cellar/litecli/1.11.0/libexec/lib/python3.12/site-packages/litecli/packages/special/main.py", line 109, in execute\n    raise CommandNotFound\nlitecli.packages.special.main.CommandNotFound\n\nDuring handling of the above exception, another exception occurred:\n\nTraceback (most recent call last):\n  File "/home/linuxbrew/.linuxbrew/Cellar/litecli/1.11.0/libexec/lib/python3.12/site-packages/litecli/main.py", line 453, in one_iteration\n    for title, cur, headers, status in res:\n                                       ^^^\n  File "/home/linuxbrew/.linuxbrew/Cellar/litecli/1.11.0/libexec/lib/python3.12/site-packages/litecli/sqlexecute.py", line 132, in run\n    cur.execute(sql)\nsqlite3.OperationalError: near "column": syntax error\n'
2024-08-21 16:56:48,632 (19383/MainThread) litecli.main ERROR - sql: 'delete column where id=1 from users;', error: OperationalError('near "column": syntax error')
2024-08-21 16:56:48,633 (19383/MainThread) litecli.main ERROR - traceback: 'Traceback (most recent call last):\n  File "/home/linuxbrew/.linuxbrew/Cellar/litecli/1.11.0/libexec/lib/python3.12/site-packages/litecli/sqlexecute.py", line 125, in run\n    for result in special.execute(cur, sql):\n                  ^^^^^^^^^^^^^^^^^^^^^^^^^\n  File "/home/linuxbrew/.linuxbrew/Cellar/litecli/1.11.0/libexec/lib/python3.12/site-packages/litecli/packages/special/main.py", line 109, in execute\n    raise CommandNotFound\nlitecli.packages.special.main.CommandNotFound\n\nDuring handling of the above exception, another exception occurred:\n\nTraceback (most recent call last):\n  File "/home/linuxbrew/.linuxbrew/Cellar/litecli/1.11.0/libexec/lib/python3.12/site-packages/litecli/main.py", line 453, in one_iteration\n    for title, cur, headers, status in res:\n                                       ^^^\n  File "/home/linuxbrew/.linuxbrew/Cellar/litecli/1.11.0/libexec/lib/python3.12/site-packages/litecli/sqlexecute.py", line 132, in run\n    cur.execute(sql)\nsqlite3.OperationalError: near "column": syntax error\n'
2024-08-21 16:58:16,806 (19383/MainThread) litecli.main ERROR - sql: 'delete row where id=1 from users', error: OperationalError('near "row": syntax error')
2024-08-21 16:58:16,808 (19383/MainThread) litecli.main ERROR - traceback: 'Traceback (most recent call last):\n  File "/home/linuxbrew/.linuxbrew/Cellar/litecli/1.11.0/libexec/lib/python3.12/site-packages/litecli/sqlexecute.py", line 125, in run\n    for result in special.execute(cur, sql):\n                  ^^^^^^^^^^^^^^^^^^^^^^^^^\n  File "/home/linuxbrew/.linuxbrew/Cellar/litecli/1.11.0/libexec/lib/python3.12/site-packages/litecli/packages/special/main.py", line 109, in execute\n    raise CommandNotFound\nlitecli.packages.special.main.CommandNotFound\n\nDuring handling of the above exception, another exception occurred:\n\nTraceback (most recent call last):\n  File "/home/linuxbrew/.linuxbrew/Cellar/litecli/1.11.0/libexec/lib/python3.12/site-packages/litecli/main.py", line 453, in one_iteration\n    for title, cur, headers, status in res:\n                                       ^^^\n  File "/home/linuxbrew/.linuxbrew/Cellar/litecli/1.11.0/libexec/lib/python3.12/site-packages/litecli/sqlexecute.py", line 132, in run\n    cur.execute(sql)\nsqlite3.OperationalError: near "row": syntax error\n'
2024-08-22 14:41:01,357 (19682/MainThread) litecli.main ERROR - sql: 'dr', error: OperationalError('near "dr": syntax error')
2024-08-22 14:41:01,370 (19682/MainThread) litecli.main ERROR - traceback: 'Traceback (most recent call last):\n  File "/home/linuxbrew/.linuxbrew/Cellar/litecli/1.11.0/libexec/lib/python3.12/site-packages/litecli/sqlexecute.py", line 125, in run\n    for result in special.execute(cur, sql):\n                  ^^^^^^^^^^^^^^^^^^^^^^^^^\n  File "/home/linuxbrew/.linuxbrew/Cellar/litecli/1.11.0/libexec/lib/python3.12/site-packages/litecli/packages/special/main.py", line 109, in execute\n    raise CommandNotFound\nlitecli.packages.special.main.CommandNotFound\n\nDuring handling of the above exception, another exception occurred:\n\nTraceback (most recent call last):\n  File "/home/linuxbrew/.linuxbrew/Cellar/litecli/1.11.0/libexec/lib/python3.12/site-packages/litecli/main.py", line 453, in one_iteration\n    for title, cur, headers, status in res:\n                                       ^^^\n  File "/home/linuxbrew/.linuxbrew/Cellar/litecli/1.11.0/libexec/lib/python3.12/site-packages/litecli/sqlexecute.py", line 132, in run\n    cur.execute(sql)\nsqlite3.OperationalError: near "dr": syntax error\n'
2024-08-22 14:42:59,380 (36846/MainThread) litecli.main ERROR - sql: '.databases', error: OperationalError('Not connected to database.')
2024-08-22 14:42:59,382 (36846/MainThread) litecli.main ERROR - traceback: 'Traceback (most recent call last):\n  File "/home/linuxbrew/.linuxbrew/Cellar/litecli/1.11.0/libexec/lib/python3.12/site-packages/litecli/main.py", line 453, in one_iteration\n    for title, cur, headers, status in res:\n                                       ^^^\n  File "/home/linuxbrew/.linuxbrew/Cellar/litecli/1.11.0/libexec/lib/python3.12/site-packages/litecli/sqlexecute.py", line 118, in run\n    raise OperationalError("Not connected to database.")\nsqlite3.OperationalError: Not connected to database.\n'
2024-08-22 14:43:17,079 (36846/MainThread) litecli.main ERROR - sql: '.exit', error: OperationalError('Not connected to database.')
2024-08-22 14:43:17,080 (36846/MainThread) litecli.main ERROR - traceback: 'Traceback (most recent call last):\n  File "/home/linuxbrew/.linuxbrew/Cellar/litecli/1.11.0/libexec/lib/python3.12/site-packages/litecli/main.py", line 453, in one_iteration\n    for title, cur, headers, status in res:\n                                       ^^^\n  File "/home/linuxbrew/.linuxbrew/Cellar/litecli/1.11.0/libexec/lib/python3.12/site-packages/litecli/sqlexecute.py", line 118, in run\n    raise OperationalError("Not connected to database.")\nsqlite3.OperationalError: Not connected to database.\n'
2024-08-22 14:43:19,292 (36846/MainThread) litecli.main ERROR - sql: '.exit', error: OperationalError('Not connected to database.')
2024-08-22 14:43:19,292 (36846/MainThread) litecli.main ERROR - traceback: 'Traceback (most recent call last):\n  File "/home/linuxbrew/.linuxbrew/Cellar/litecli/1.11.0/libexec/lib/python3.12/site-packages/litecli/main.py", line 453, in one_iteration\n    for title, cur, headers, status in res:\n                                       ^^^\n  File "/home/linuxbrew/.linuxbrew/Cellar/litecli/1.11.0/libexec/lib/python3.12/site-packages/litecli/sqlexecute.py", line 118, in run\n    raise OperationalError("Not connected to database.")\nsqlite3.OperationalError: Not connected to database.\n'
2024-08-22 14:43:20,697 (36846/MainThread) litecli.main ERROR - sql: '.exit', error: OperationalError('Not connected to database.')
2024-08-22 14:43:20,698 (36846/MainThread) litecli.main ERROR - traceback: 'Traceback (most recent call last):\n  File "/home/linuxbrew/.linuxbrew/Cellar/litecli/1.11.0/libexec/lib/python3.12/site-packages/litecli/main.py", line 453, in one_iteration\n    for title, cur, headers, status in res:\n                                       ^^^\n  File "/home/linuxbrew/.linuxbrew/Cellar/litecli/1.11.0/libexec/lib/python3.12/site-packages/litecli/sqlexecute.py", line 118, in run\n    raise OperationalError("Not connected to database.")\nsqlite3.OperationalError: Not connected to database.\n'
2024-08-23 01:21:32,435 (36952/MainThread) litecli.main ERROR - sql: 'DELETE FROM users,blogs', error: OperationalError('near ",": syntax error')
2024-08-23 01:21:32,453 (36952/MainThread) litecli.main ERROR - traceback: 'Traceback (most recent call last):\n  File "/home/linuxbrew/.linuxbrew/Cellar/litecli/1.11.0/libexec/lib/python3.12/site-packages/litecli/sqlexecute.py", line 125, in run\n    for result in special.execute(cur, sql):\n                  ^^^^^^^^^^^^^^^^^^^^^^^^^\n  File "/home/linuxbrew/.linuxbrew/Cellar/litecli/1.11.0/libexec/lib/python3.12/site-packages/litecli/packages/special/main.py", line 109, in execute\n    raise CommandNotFound\nlitecli.packages.special.main.CommandNotFound\n\nDuring handling of the above exception, another exception occurred:\n\nTraceback (most recent call last):\n  File "/home/linuxbrew/.linuxbrew/Cellar/litecli/1.11.0/libexec/lib/python3.12/site-packages/litecli/main.py", line 453, in one_iteration\n    for title, cur, headers, status in res:\n                                       ^^^\n  File "/home/linuxbrew/.linuxbrew/Cellar/litecli/1.11.0/libexec/lib/python3.12/site-packages/litecli/sqlexecute.py", line 132, in run\n    cur.execute(sql)\nsqlite3.OperationalError: near ",": syntax error\n'
2024-08-23 01:21:39,589 (36952/MainThread) litecli.main ERROR - sql: 'DELETE FROM users blogs', error: OperationalError('near "blogs": syntax error')
2024-08-23 01:21:39,589 (36952/MainThread) litecli.main ERROR - traceback: 'Traceback (most recent call last):\n  File "/home/linuxbrew/.linuxbrew/Cellar/litecli/1.11.0/libexec/lib/python3.12/site-packages/litecli/sqlexecute.py", line 125, in run\n    for result in special.execute(cur, sql):\n                  ^^^^^^^^^^^^^^^^^^^^^^^^^\n  File "/home/linuxbrew/.linuxbrew/Cellar/litecli/1.11.0/libexec/lib/python3.12/site-packages/litecli/packages/special/main.py", line 109, in execute\n    raise CommandNotFound\nlitecli.packages.special.main.CommandNotFound\n\nDuring handling of the above exception, another exception occurred:\n\nTraceback (most recent call last):\n  File "/home/linuxbrew/.linuxbrew/Cellar/litecli/1.11.0/libexec/lib/python3.12/site-packages/litecli/main.py", line 453, in one_iteration\n    for title, cur, headers, status in res:\n                                       ^^^\n  File "/home/linuxbrew/.linuxbrew/Cellar/litecli/1.11.0/libexec/lib/python3.12/site-packages/litecli/sqlexecute.py", line 132, in run\n    cur.execute(sql)\nsqlite3.OperationalError: near "blogs": syntax error\n'
2024-08-23 01:45:19,175 (36952/MainThread) litecli.main ERROR - sql: 'DROP', error: OperationalError('incomplete input')
2024-08-23 01:45:19,176 (36952/MainThread) litecli.main ERROR - traceback: 'Traceback (most recent call last):\n  File "/home/linuxbrew/.linuxbrew/Cellar/litecli/1.11.0/libexec/lib/python3.12/site-packages/litecli/sqlexecute.py", line 125, in run\n    for result in special.execute(cur, sql):\n                  ^^^^^^^^^^^^^^^^^^^^^^^^^\n  File "/home/linuxbrew/.linuxbrew/Cellar/litecli/1.11.0/libexec/lib/python3.12/site-packages/litecli/packages/special/main.py", line 109, in execute\n    raise CommandNotFound\nlitecli.packages.special.main.CommandNotFound\n\nDuring handling of the above exception, another exception occurred:\n\nTraceback (most recent call last):\n  File "/home/linuxbrew/.linuxbrew/Cellar/litecli/1.11.0/libexec/lib/python3.12/site-packages/litecli/main.py", line 453, in one_iteration\n    for title, cur, headers, status in res:\n                                       ^^^\n  File "/home/linuxbrew/.linuxbrew/Cellar/litecli/1.11.0/libexec/lib/python3.12/site-packages/litecli/sqlexecute.py", line 132, in run\n    cur.execute(sql)\nsqlite3.OperationalError: incomplete input\n'
2024-08-23 01:48:33,096 (69889/MainThread) litecli.main ERROR - sql: 'PRAGMA ta  blogs', error: OperationalError('near "blogs": syntax error')
2024-08-23 01:48:33,097 (69889/MainThread) litecli.main ERROR - traceback: 'Traceback (most recent call last):\n  File "/home/linuxbrew/.linuxbrew/Cellar/litecli/1.11.0/libexec/lib/python3.12/site-packages/litecli/sqlexecute.py", line 125, in run\n    for result in special.execute(cur, sql):\n                  ^^^^^^^^^^^^^^^^^^^^^^^^^\n  File "/home/linuxbrew/.linuxbrew/Cellar/litecli/1.11.0/libexec/lib/python3.12/site-packages/litecli/packages/special/main.py", line 109, in execute\n    raise CommandNotFound\nlitecli.packages.special.main.CommandNotFound\n\nDuring handling of the above exception, another exception occurred:\n\nTraceback (most recent call last):\n  File "/home/linuxbrew/.linuxbrew/Cellar/litecli/1.11.0/libexec/lib/python3.12/site-packages/litecli/main.py", line 453, in one_iteration\n    for title, cur, headers, status in res:\n                                       ^^^\n  File "/home/linuxbrew/.linuxbrew/Cellar/litecli/1.11.0/libexec/lib/python3.12/site-packages/litecli/sqlexecute.py", line 132, in run\n    cur.execute(sql)\nsqlite3.OperationalError: near "blogs": syntax error\n'
2024-08-23 02:13:29,517 (69889/MainThread) litecli.main ERROR - sql: 'DELETE * FROM users WHERE id=1', error: OperationalError('near "*": syntax error')
2024-08-23 02:13:29,518 (69889/MainThread) litecli.main ERROR - traceback: 'Traceback (most recent call last):\n  File "/home/linuxbrew/.linuxbrew/Cellar/litecli/1.11.0/libexec/lib/python3.12/site-packages/litecli/sqlexecute.py", line 125, in run\n    for result in special.execute(cur, sql):\n                  ^^^^^^^^^^^^^^^^^^^^^^^^^\n  File "/home/linuxbrew/.linuxbrew/Cellar/litecli/1.11.0/libexec/lib/python3.12/site-packages/litecli/packages/special/main.py", line 109, in execute\n    raise CommandNotFound\nlitecli.packages.special.main.CommandNotFound\n\nDuring handling of the above exception, another exception occurred:\n\nTraceback (most recent call last):\n  File "/home/linuxbrew/.linuxbrew/Cellar/litecli/1.11.0/libexec/lib/python3.12/site-packages/litecli/main.py", line 453, in one_iteration\n    for title, cur, headers, status in res:\n                                       ^^^\n  File "/home/linuxbrew/.linuxbrew/Cellar/litecli/1.11.0/libexec/lib/python3.12/site-packages/litecli/sqlexecute.py", line 132, in run\n    cur.execute(sql)\nsqlite3.OperationalError: near "*": syntax error\n'
2024-08-23 02:14:20,264 (69889/MainThread) litecli.main ERROR - sql: 'DELETE ROW FROM blogs WHERE id=1', error: OperationalError('near "ROW": syntax error')
2024-08-23 02:14:20,265 (69889/MainThread) litecli.main ERROR - traceback: 'Traceback (most recent call last):\n  File "/home/linuxbrew/.linuxbrew/Cellar/litecli/1.11.0/libexec/lib/python3.12/site-packages/litecli/sqlexecute.py", line 125, in run\n    for result in special.execute(cur, sql):\n                  ^^^^^^^^^^^^^^^^^^^^^^^^^\n  File "/home/linuxbrew/.linuxbrew/Cellar/litecli/1.11.0/libexec/lib/python3.12/site-packages/litecli/packages/special/main.py", line 109, in execute\n    raise CommandNotFound\nlitecli.packages.special.main.CommandNotFound\n\nDuring handling of the above exception, another exception occurred:\n\nTraceback (most recent call last):\n  File "/home/linuxbrew/.linuxbrew/Cellar/litecli/1.11.0/libexec/lib/python3.12/site-packages/litecli/main.py", line 453, in one_iteration\n    for title, cur, headers, status in res:\n                                       ^^^\n  File "/home/linuxbrew/.linuxbrew/Cellar/litecli/1.11.0/libexec/lib/python3.12/site-packages/litecli/sqlexecute.py", line 132, in run\n    cur.execute(sql)\nsqlite3.OperationalError: near "ROW": syntax error\n'
2024-08-23 07:19:25,742 (135369/MainThread) litecli.main ERROR - traceback: 'Traceback (most recent call last):\n  File "/home/linuxbrew/.linuxbrew/Cellar/litecli/1.11.0/libexec/lib/python3.12/site-packages/litecli/main.py", line 324, in connect\n    _connect()\n  File "/home/linuxbrew/.linuxbrew/Cellar/litecli/1.11.0/libexec/lib/python3.12/site-packages/litecli/main.py", line 321, in _connect\n    self.sqlexecute = SQLExecute(database)\n                      ^^^^^^^^^^^^^^^^^^^^\n  File "/home/linuxbrew/.linuxbrew/Cellar/litecli/1.11.0/libexec/lib/python3.12/site-packages/litecli/sqlexecute.py", line 57, in __init__\n    self.connect()\n  File "/home/linuxbrew/.linuxbrew/Cellar/litecli/1.11.0/libexec/lib/python3.12/site-packages/litecli/sqlexecute.py", line 66, in connect\n    raise Exception("Path does not exist: {}".format(db_dir_name))\nException: Path does not exist: /home/yogix/CodeSpace/FASTAPI/fast_app/CodeSpace/FASTAPI/fast_app/blog\n'
2024-08-24 01:41:43,384 (345222/MainThread) litecli.main ERROR - traceback: 'Traceback (most recent call last):\n  File "/home/linuxbrew/.linuxbrew/Cellar/litecli/1.11.0/libexec/lib/python3.12/site-packages/litecli/main.py", line 324, in connect\n    _connect()\n  File "/home/linuxbrew/.linuxbrew/Cellar/litecli/1.11.0/libexec/lib/python3.12/site-packages/litecli/main.py", line 321, in _connect\n    self.sqlexecute = SQLExecute(database)\n                      ^^^^^^^^^^^^^^^^^^^^\n  File "/home/linuxbrew/.linuxbrew/Cellar/litecli/1.11.0/libexec/lib/python3.12/site-packages/litecli/sqlexecute.py", line 57, in __init__\n    self.connect()\n  File "/home/linuxbrew/.linuxbrew/Cellar/litecli/1.11.0/libexec/lib/python3.12/site-packages/litecli/sqlexecute.py", line 66, in connect\n    raise Exception("Path does not exist: {}".format(db_dir_name))\nException: Path does not exist: /home/yogix/CodeSpace/FASTAPI/fast_app/blog\n'
2024-08-24 11:07:17,209 (48153/MainThread) litecli.main ERROR - traceback: 'Traceback (most recent call last):\n  File "/home/linuxbrew/.linuxbrew/Cellar/litecli/1.11.0/libexec/lib/python3.12/site-packages/litecli/main.py", line 324, in connect\n    _connect()\n  File "/home/linuxbrew/.linuxbrew/Cellar/litecli/1.11.0/libexec/lib/python3.12/site-packages/litecli/main.py", line 321, in _connect\n    self.sqlexecute = SQLExecute(database)\n                      ^^^^^^^^^^^^^^^^^^^^\n  File "/home/linuxbrew/.linuxbrew/Cellar/litecli/1.11.0/libexec/lib/python3.12/site-packages/litecli/sqlexecute.py", line 57, in __init__\n    self.connect()\n  File "/home/linuxbrew/.linuxbrew/Cellar/litecli/1.11.0/libexec/lib/python3.12/site-packages/litecli/sqlexecute.py", line 66, in connect\n    raise Exception("Path does not exist: {}".format(db_dir_name))\nException: Path does not exist: /home/yogix/CodeSpace/FASTAPI/fast_app/app/postgresql+psycopg2:/default:msq78RwNxTIE@ep-curly-king-a1cx2zm9-pooler.ap-southeast-1.aws.neon.tech:5432\n'
2024-08-24 11:07:52,033 (48274/MainThread) litecli.main ERROR - traceback: 'Traceback (most recent call last):\n  File "/home/linuxbrew/.linuxbrew/Cellar/litecli/1.11.0/libexec/lib/python3.12/site-packages/litecli/main.py", line 324, in connect\n    _connect()\n  File "/home/linuxbrew/.linuxbrew/Cellar/litecli/1.11.0/libexec/lib/python3.12/site-packages/litecli/main.py", line 321, in _connect\n    self.sqlexecute = SQLExecute(database)\n                      ^^^^^^^^^^^^^^^^^^^^\n  File "/home/linuxbrew/.linuxbrew/Cellar/litecli/1.11.0/libexec/lib/python3.12/site-packages/litecli/sqlexecute.py", line 57, in __init__\n    self.connect()\n  File "/home/linuxbrew/.linuxbrew/Cellar/litecli/1.11.0/libexec/lib/python3.12/site-packages/litecli/sqlexecute.py", line 66, in connect\n    raise Exception("Path does not exist: {}".format(db_dir_name))\nException: Path does not exist: /home/yogix/CodeSpace/FASTAPI/fast_app/app/postgresql+psycopg2:/default:msq78RwNxTIE@ep-curly-king-a1cx2zm9-pooler.ap-southeast-1.aws.neon.tech:5432\n'
2024-08-24 11:09:49,572 (48623/MainThread) litecli.main ERROR - traceback: 'Traceback (most recent call last):\n  File "/home/linuxbrew/.linuxbrew/Cellar/litecli/1.11.0/libexec/lib/python3.12/site-packages/litecli/main.py", line 324, in connect\n    _connect()\n  File "/home/linuxbrew/.linuxbrew/Cellar/litecli/1.11.0/libexec/lib/python3.12/site-packages/litecli/main.py", line 321, in _connect\n    self.sqlexecute = SQLExecute(database)\n                      ^^^^^^^^^^^^^^^^^^^^\n  File "/home/linuxbrew/.linuxbrew/Cellar/litecli/1.11.0/libexec/lib/python3.12/site-packages/litecli/sqlexecute.py", line 57, in __init__\n    self.connect()\n  File "/home/linuxbrew/.linuxbrew/Cellar/litecli/1.11.0/libexec/lib/python3.12/site-packages/litecli/sqlexecute.py", line 66, in connect\n    raise Exception("Path does not exist: {}".format(db_dir_name))\nException: Path does not exist: /home/yogix/CodeSpace/FASTAPI/fast_app/app/postgres:/default:msq78RwNxTIE@ep-curly-king-a1cx2zm9-pooler.ap-southeast-1.aws.neon.tech:5432\n'
